Workbook
Name Category: #REF!
Name Transaction: #REF!

Sheet Data
A1: 이름 | B1: 월 | C1: 매출액 | D1: 목표매출액 | E1: 전년도매출액 | F1: 전체고객수 | G1: 목표신규고객수 | H1: 신규고객수 | I1: 전년도신규고객수 | J1: 고객확보비용 | K1: 고객확보비용목표(고객당) | L1: 전년도고객확보비용(고객당) | M1: 전년도매출액(고객당) | N1: 목표매출액(고객당)
A2: 김기범 | B2: 1월 | C2: 152000 | D2: 193000 | E2: 153000 | F2: 68 | G2: 40 | H2: 17 | I2: 14 | J2: 5300 | K2: 350 | L2: 410 | M2: 3100 | N2: 2500
A3: 김기범 | B3: 2월 | C3: 111000 | D3: 144000 | E3: 132000 | F3: 80 | G3: 33 | H3: 16 | I3: 21 | J3: 7900 | K3: 350 | L3: 405 | M3: 2600 | N3: 2600
A4: 김기범 | B4: 3월 | C4: 182000 | D4: 169000 | E4: 164000 | F4: 80 | G4: 37 | H4: 18 | I4: 13 | J4: 7900 | K4: 350 | L4: 398 | M4: 2400 | N4: 2400
A5: 김기범 | B5: 4월 | C5: 104000 | D5: 126000 | E5: 115000 | F5: 68 | G5: 75 | H5: 18 | I5: 9 | J5: 9800 | K5: 400 | L5: 404 | M5: 2500 | N5: 2700
A6: 김기범 | B6: 5월 | C6: 190000 | D6: 128000 | E6: 119000 | F6: 78 | G6: 78 | H6: 21 | I6: 23 | J6: 8700 | K6: 350 | L6: 379 | M6: 2500 | N6: 2500
A7: 김기범 | B7: 6월 | C7: 121000 | D7: 196000 | E7: 124000 | F7: 80 | G7: 69 | H7: 14 | I7: 14 | J7: 5600 | K7: 350 | L7: 386 | M7: 2000 | N7: 2600
A8: 김기범 | B8: 7월 | C8: 157000 | D8: 128000 | E8: 103000 | F8: 35 | G8: 39 | H8: 5 | I8: 9 | J8: 5900 | K8: 350 | L8: 353 | M8: 2200 | N8: 2200
A9: 김기범 | B9: 8월 | C9: 118000 | D9: 162000 | E9: 151000 | F9: 55 | G9: 80 | H9: 15 | I9: 16 | J9: 6500 | K9: 450 | L9: 388 | M9: 2300 | N9: 2300
A10: 김기범 | B10: 9월 | C10: 118000 | D10: 130000 | E10: 119000 | F10: 60 | G10: 52 | H10: 17 | I10: 19 | J10: 9600 | K10: 350 | L10: 365 | M10: 2400 | N10: 2500
A11: 김기범 | B11: 10월 | C11: 140000 | D11: 132000 | E11: 125000 | F11: 37 | G11: 56 | H11: 10 | I11: 21 | J11: 7500 | K11: 350 | L11: 396 | M11: 2500 | N11: 2450
A12: 김기범 | B12: 11월 | C12: 179000 | D12: 149000 | E12: 125000 | F12: 30 | G12: 81 | H12: 7 | I12: 19 | J12: 8600 | K12: 350 | L12: 386 | M12: 2600 | N12: 2700
A13: 김기범 | B13: 12월 | C13: 158000 | D13: 152000 | E13: 182000 | F13: 75 | G13: 63 | H13: 8 | I13: 9 | J13: 9100 | K13: 300 | L13: 364 | M13: 2900 | N13: 2350
... A61: 박지수 | B61: 12월 | C61: 127000 | D61: 190000 | E61: 141000 | F61: 77 | G61: 36 | H61: 16 | I61: 13 | J61: 7700 | K61: 300 | L61: 406 | M61: 2400 | N61: 2350

Sheet Calculations
H1: Q1 2023
H2: Q2 2023
H3: Q3 2023
H4: Q4 2023
B5: =DASHBOARD!F2 -> Q4 2023
C8: Q1
C9: =_xlfn.SWITCH($B$5, $H$1, C28, $H$2, C39, $H$3, C50, $H$4, C61) -> 10월 | D9: =_xlfn.SWITCH($B$5, $H$1, D28, $H$2, D39, $H$3, D50, $H$4, D61) -> 11월 | E9: =_xlfn.SWITCH($B$5, $H$1, E28, $H$2, E39, $H$3, E50, $H$4, E61) -> 12월 | F9: =_xlfn.SWITCH($B$5, $H$1, F28, $H$2, F39, $H$3, F50, $H$4, F61) -> 10월 | G9: =_xlfn.SWITCH($B$5, $H$1, G28, $H$2, G39, $H$3, G50, $H$4, G61) -> 11월 | H9: =_xlfn.SWITCH($B$5, $H$1, H28, $H$2, H39, $H$3, H50, $H$4, H61) -> 12월 | I9: =_xlfn.SWITCH($B$5, $H$1, I28, $H$2, I39, $H$3, I50, $H$4, I61) -> 10월 | J9: =_xlfn.SWITCH($B$5, $H$1, J28, $H$2, J39, $H$3, J50, $H$4, J61) -> 11월 | ... AR9: =_xlfn.SWITCH($B$5, $H$1, AR28, $H$2, AR39, $H$3, AR50, $H$4, AR61) -> 12월
C10: 매출액 | D10: 매출액 | E10: 매출액 | F10: 목표 매출액 | G10: 목표 매출액 | H10: 목표 매출액 | I10: 전년도 매출액 | J10: 전년도 매출액 | K10: 전년도 매출액 | L10: 전체 고객 수 | M10: 전체 고객 수 | N10: 전체 고객 수 | O10: 목표 신규 고객 수 | P10: 목표 신규 고객 수 | Q10: 목표 신규 고객 수 | R10: 신규 고객 수 | S10: 신규 고객 수 | T10: 신규 고객 수 | U10: 전년도 신규 고객 수 | V10: 전년도 신규 고객 수 | W10: 전년도 신규 고객 수 | X10: 고객 확보 비용 | Y10: 고객 확보 비용 | Z10: 고객 확보 비용 | AA10: 고객 당 고객 확보 비용 | AB10: 고객 당 고객 확보 비용 | AC10: 고객 당 고객 확보 비용 | AD10: 고객 당 고객 확보 비용 목표 | AE10: 고객 당 고객 확보 비용 목표 | AF10: 고객 당 고객 확보 비용 목표 | AG10: 전년도 고객 확보 비용 (고객 당) | AH10: 전년도 고객 확보 비용 (고객 당) | AI10: 전년도 고객 확보 비용 (고객 당) | AJ10: 매출액 (고객당) | AK10: 매출액 (고객당) | AL10: 매출액 (고객당) | AM10: 전년도 매출액 (고객당) | AN10: 전년도 매출액 (고객당) | AO10: 전년도 매출액 (고객당) | AP10: 목표 매출액 (고객당) | AQ10: 목표 매출액 (고객당) | AR10: 목표 매출액 (고객당)
B11: =_xlfn.SWITCH($B$5, $H$1, B30, $H$2, B41, $H$3, B52, $H$4, B63) -> 김기범 | C11: =_xlfn.SWITCH($B$5, $H$1, C30, $H$2, C41, $H$3, C52, $H$4, C63) -> 140000 | D11: =_xlfn.SWITCH($B$5, $H$1, D30, $H$2, D41, $H$3, D52, $H$4, D63) -> 179000 | E11: =_xlfn.SWITCH($B$5, $H$1, E30, $H$2, E41, $H$3, E52, $H$4, E63) -> 158000 | F11: =_xlfn.SWITCH($B$5, $H$1, F30, $H$2, F41, $H$3, F52, $H$4, F63) -> 132000 | G11: =_xlfn.SWITCH($B$5, $H$1, G30, $H$2, G41, $H$3, G52, $H$4, G63) -> 149000 | H11: =_xlfn.SWITCH($B$5, $H$1, H30, $H$2, H41, $H$3, H52, $H$4, H63) -> 152000 | I11: =_xlfn.SWITCH($B$5, $H$1, I30, $H$2, I41, $H$3, I52, $H$4, I63) -> 125000 | ... AR11: =_xlfn.SWITCH($B$5, $H$1, AR30, $H$2, AR41, $H$3, AR52, $H$4, AR63) -> 2350
B12: =_xlfn.SWITCH($B$5, $H$1, B31, $H$2, B42, $H$3, B53, $H$4, B64) -> 안동휘 | C12: =_xlfn.SWITCH($B$5, $H$1, C31, $H$2, C42, $H$3, C53, $H$4, C64) -> 137000 | D12: =_xlfn.SWITCH($B$5, $H$1, D31, $H$2, D42, $H$3, D53, $H$4, D64) -> 171000 | E12: =_xlfn.SWITCH($B$5, $H$1, E31, $H$2, E42, $H$3, E53, $H$4, E64) -> 103000 | F12: =_xlfn.SWITCH($B$5, $H$1, F31, $H$2, F42, $H$3, F53, $H$4, F64) -> 136000 | G12: =_xlfn.SWITCH($B$5, $H$1, G31, $H$2, G42, $H$3, G53, $H$4, G64) -> 171000 | H12: =_xlfn.SWITCH($B$5, $H$1, H31, $H$2, H42, $H$3, H53, $H$4, H64) -> 158000 | I12: =_xlfn.SWITCH($B$5, $H$1, I31, $H$2, I42, $H$3, I53, $H$4, I64) -> 115000 | ... AR12: =_xlfn.SWITCH($B$5, $H$1, AR31, $H$2, AR42, $H$3, AR53, $H$4, AR64) -> 2350
B13: =_xlfn.SWITCH($B$5, $H$1, B32, $H$2, B43, $H$3, B54, $H$4, B65) -> 남범수 | C13: =_xlfn.SWITCH($B$5, $H$1, C32, $H$2, C43, $H$3, C54, $H$4, C65) -> 180000 | D13: =_xlfn.SWITCH($B$5, $H$1, D32, $H$2, D43, $H$3, D54, $H$4, D65) -> 170000 | E13: =_xlfn.SWITCH($B$5, $H$1, E32, $H$2, E43, $H$3, E54, $H$4, E65) -> 138000 | F13: =_xlfn.SWITCH($B$5, $H$1, F32, $H$2, F43, $H$3, F54, $H$4, F65) -> 138000 | G13: =_xlfn.SWITCH($B$5, $H$1, G32, $H$2, G43, $H$3, G54, $H$4, G65) -> 134000 | H13: =_xlfn.SWITCH($B$5, $H$1, H32, $H$2, H43, $H$3, H54, $H$4, H65) -> 124000 | I13: =_xlfn.SWITCH($B$5, $H$1, I32, $H$2, I43, $H$3, I54, $H$4, I65) -> 144000 | ... AR13: =_xlfn.SWITCH($B$5, $H$1, AR32, $H$2, AR43, $H$3, AR54, $H$4, AR65) -> 2350
B14: =_xlfn.SWITCH($B$5, $H$1, B33, $H$2, B44, $H$3, B55, $H$4, B66) -> 오지훈 | C14: =_xlfn.SWITCH($B$5, $H$1, C33, $H$2, C44, $H$3, C55, $H$4, C66) -> 164000 | D14: =_xlfn.SWITCH($B$5, $H$1, D33, $H$2, D44, $H$3, D55, $H$4, D66) -> 138000 | E14: =_xlfn.SWITCH($B$5, $H$1, E33, $H$2, E44, $H$3, E55, $H$4, E66) -> 178000 | F14: =_xlfn.SWITCH($B$5, $H$1, F33, $H$2, F44, $H$3, F55, $H$4, F66) -> 175000 | G14: =_xlfn.SWITCH($B$5, $H$1, G33, $H$2, G44, $H$3, G55, $H$4, G66) -> 186000 | H14: =_xlfn.SWITCH($B$5, $H$1, H33, $H$2, H44, $H$3, H55, $H$4, H66) -> 179000 | I14: =_xlfn.SWITCH($B$5, $H$1, I33, $H$2, I44, $H$3, I55, $H$4, I66) -> 169000 | ... AR14: =_xlfn.SWITCH($B$5, $H$1, AR33, $H$2, AR44, $H$3, AR55, $H$4, AR66) -> 2350
B15: =_xlfn.SWITCH($B$5, $H$1, B34, $H$2, B45, $H$3, B56, $H$4, B67) -> 박지수 | C15: =_xlfn.SWITCH($B$5, $H$1, C34, $H$2, C45, $H$3, C56, $H$4, C67) -> 121000 | D15: =_xlfn.SWITCH($B$5, $H$1, D34, $H$2, D45, $H$3, D56, $H$4, D67) -> 176000 | E15: =_xlfn.SWITCH($B$5, $H$1, E34, $H$2, E45, $H$3, E56, $H$4, E67) -> 127000 | F15: =_xlfn.SWITCH($B$5, $H$1, F34, $H$2, F45, $H$3, F56, $H$4, F67) -> 145000 | G15: =_xlfn.SWITCH($B$5, $H$1, G34, $H$2, G45, $H$3, G56, $H$4, G67) -> 125000 | H15: =_xlfn.SWITCH($B$5, $H$1, H34, $H$2, H45, $H$3, H56, $H$4, H67) -> 190000 | I15: =_xlfn.SWITCH($B$5, $H$1, I34, $H$2, I45, $H$3, I56, $H$4, I67) -> 169000 | ... AR15: =_xlfn.SWITCH($B$5, $H$1, AR34, $H$2, AR45, $H$3, AR56, $H$4, AR67) -> 2350
B16: 총합 | C16: =SUM(C11:C15) -> 742000 | D16: =SUM(D11:D15) -> 834000 | E16: =SUM(E11:E15) -> 704000 | F16: =SUM(F11:F15) -> 726000 | G16: =SUM(G11:G15) -> 765000 | H16: =SUM(H11:H15) -> 803000 | I16: =SUM(I11:I15) -> 722000 | J16: =SUM(J11:J15) -> 670000 | ... Z16: =SUM(Z11:Z15) -> 42700 | AA16: =AVERAGE(AA11:AA15) -> 1055.1948 | AB16: =AVERAGE(AB11:AB15) -> 894.3759 | AC16: =AVERAGE(AC11:AC15) -> 1060.9167 | AD16: =AVERAGE(AD11:AD15) -> 350 | AE16: =AVERAGE(AE11:AE15) -> 350 | AF16: =AVERAGE(AF11:AF15) -> 300 | AG16: =AVERAGE(AG11:AG15) -> 386 | AH16: =AVERAGE(AH11:AH15) -> 382.4 | ... AR16: =AVERAGE(AR11:AR15) -> 2350
B18: 연간 총 매출액 | D18: =SUM(Calculations!C35:E35,Calculations!C46:E46,Calculations!C57:E57,Calculations!C68:E68) -> 8779000
B19: 연간 총 고객 수 | D19: =SUM(L35:N35,L46:N46,L57:N57,L68:N68) -> 3548
B20: 연간 신규 고객 수 | D20: =SUM(R35:T35,R46:T46,R57:T57,R68:T68) -> 713
B21: 고객 당 매출액 | D21: =D18/D19 -> 2474.3517
C27: =H1 -> Q1 2023
C28: 1월 | D28: 2월 | E28: 3월 | F28: 1월 | G28: 2월 | H28: 3월 | I28: 1월 | J28: 2월 | K28: 3월 | L28: 1월 | M28: 2월 | N28: 3월 | O28: 1월 | P28: 2월 | Q28: 3월 | R28: 1월 | S28: 2월 | T28: 3월 | U28: 1월 | V28: 2월 | W28: 3월 | X28: 1월 | Y28: 2월 | Z28: 3월 | AA28: 1월 | AB28: 2월 | AC28: 3월 | AD28: 1월 | AE28: 2월 | AF28: 3월 | AG28: 1월 | AH28: 2월 | AI28: 3월 | AJ28: 1월 | AK28: 2월 | AL28: 3월 | AM28: 1월 | AN28: 2월 | AO28: 3월 | AP28: 1월 | AQ28: 2월 | AR28: 3월
C29: 매출액 | D29: 매출액 | E29: 매출액 | F29: 목표 매출액 | G29: 목표 매출액 | H29: 목표 매출액 | I29: 전년도 매출액 | J29: 전년도 매출액 | K29: 전년도 매출액 | L29: 전체 고객 수 | M29: 전체 고객 수 | N29: 전체 고객 수 | O29: 목표 신규 고객 수 | P29: 목표 신규 고객 수 | Q29: 목표 신규 고객 수 | R29: 신규 고객 수 | S29: 신규 고객 수 | T29: 신규 고객 수 | U29: 전년도 신규 고객 수 | V29: 전년도 신규 고객 수 | W29: 전년도 신규 고객 수 | X29: 고객 확보 비용 | Y29: 고객 확보 비용 | Z29: 고객 확보 비용 | AA29: 고객 당 고객 확보 비용 | AB29: 고객 당 고객 확보 비용 | AC29: 고객 당 고객 확보 비용 | AD29: 고객 확보 비용 목표 (고객 당) | AE29: 고객 확보 비용 목표 (고객 당) | AF29: 고객 확보 비용 목표 (고객 당) | AG29: 전년도 고객 확보 비용 (고객 당) | AH29: 전년도 고객 확보 비용 (고객 당) | AI29: 전년도 고객 확보 비용 (고객 당) | AJ29: 매출액 (고객당) | AK29: 매출액 (고객당) | AL29: 매출액 (고객당) | AM29: 전년도 매출액 (고객당) | AN29: 전년도 매출액 (고객당) | AO29: 전년도 매출액 (고객당) | AP29: 목표 매출액 (고객당) | AQ29: 목표 매출액 (고객당) | AR29: 목표 매출액 (고객당)
B30: 김기범 | C30: {=INDEX(표2[매출액],MATCH($B30&C$28,표2[이름]&표2[월],0),1)} -> 152000 | D30: {=INDEX(표2[매출액],MATCH($B30&D$28,표2[이름]&표2[월],0),1)} -> 111000 | E30: {=INDEX(표2[매출액],MATCH($B30&E$28,표2[이름]&표2[월],0),1)} -> 182000 | F30: {=INDEX(표2[목표매출액],MATCH($B30&F$28,표2[이름]&표2[월],0),1)} -> 193000 | G30: {=INDEX(표2[목표매출액],MATCH($B30&G$28,표2[이름]&표2[월],0),1)} -> 144000 | H30: {=INDEX(표2[목표매출액],MATCH($B30&H$28,표2[이름]&표2[월],0),1)} -> 169000 | I30: {=INDEX(표2[전년도매출액],MATCH($B30&I$28,표2[이름]&표2[월],0),1)} -> 153000 | J30: {=INDEX(표2[전년도매출액],MATCH($B30&J$28,표2[이름]&표2[월],0),1)} -> 132000 | K30: {=INDEX(표2[전년도매출액],MATCH($B30&K$28,표2[이름]&표2[월],0),1)} -> 164000 | L30: {=INDEX(표2[전체고객수],MATCH($B30&L$28,표2[이름]&표2[월],0),1)} -> 68 | M30: {=INDEX(표2[전체고객수],MATCH($B30&M$28,표2[이름]&표2[월],0),1)} -> 80 | N30: {=INDEX(표2[전체고객수],MATCH($B30&N$28,표2[이름]&표2[월],0),1)} -> 80 | O30: {=INDEX(표2[목표신규고객수],MATCH($B30&O$28,표2[이름]&표2[월],0),1)} -> 40 | P30: {=INDEX(표2[목표신규고객수],MATCH($B30&P$28,표2[이름]&표2[월],0),1)} -> 33 | Q30: {=INDEX(표2[목표신규고객수],MATCH($B30&Q$28,표2[이름]&표2[월],0),1)} -> 37 | R30: {=INDEX(표2[신규고객수],MATCH($B30&R$28,표2[이름]&표2[월],0),1)} -> 17 | S30: {=INDEX(표2[신규고객수],MATCH($B30&S$28,표2[이름]&표2[월],0),1)} -> 16 | T30: {=INDEX(표2[신규고객수],MATCH($B30&T$28,표2[이름]&표2[월],0),1)} -> 18 | U30: {=INDEX(표2[전년도신규고객수],MATCH($B30&U$28,표2[이름]&표2[월],0),1)} -> 14 | V30: {=INDEX(표2[전년도신규고객수],MATCH($B30&V$28,표2[이름]&표2[월],0),1)} -> 21 | W30: {=INDEX(표2[전년도신규고객수],MATCH($B30&W$28,표2[이름]&표2[월],0),1)} -> 13 | X30: {=INDEX(표2[고객확보비용],MATCH($B30&X$28,표2[이름]&표2[월],0),1)} -> 5300 | Y30: {=INDEX(표2[고객확보비용],MATCH($B30&Y$28,표2[이름]&표2[월],0),1)} -> 7900 | Z30: {=INDEX(표2[고객확보비용],MATCH($B30&Z$28,표2[이름]&표2[월],0),1)} -> 7900 | AA30: =X30/R30 -> 311.76471 | AB30: =Y30/S30 -> 493.75 | AC30: =Z30/T30 -> 438.88889 | AD30: {=INDEX(표2[고객확보비용목표(고객당)],MATCH($B30&AD$28,표2[이름]&표2[월],0),1)} -> 350 | AE30: {=INDEX(표2[고객확보비용목표(고객당)],MATCH($B30&AE$28,표2[이름]&표2[월],0),1)} -> 350 | AF30: {=INDEX(표2[고객확보비용목표(고객당)],MATCH($B30&AF$28,표2[이름]&표2[월],0),1)} -> 350 | AG30: {=INDEX(표2[전년도고객확보비용(고객당)],MATCH($B30&AG$28,표2[이름]&표2[월],0),1)} -> 410 | AH30: {=INDEX(표2[전년도고객확보비용(고객당)],MATCH($B30&AH$28,표2[이름]&표2[월],0),1)} -> 405 | AI30: {=INDEX(표2[전년도고객확보비용(고객당)],MATCH($B30&AI$28,표2[이름]&표2[월],0),1)} -> 398 | AJ30: =C30/L30 -> 2235.2941 | AK30: =D30/M30 -> 1387.5 | AL30: =E30/N30 -> 2275 | AM30: {=INDEX(표2[전년도매출액(고객당)],MATCH($B30&AM$28,표2[이름]&표2[월],0),1)} -> 3100 | AN30: {=INDEX(표2[전년도매출액(고객당)],MATCH($B30&AN$28,표2[이름]&표2[월],0),1)} -> 2600 | AO30: {=INDEX(표2[전년도매출액(고객당)],MATCH($B30&AO$28,표2[이름]&표2[월],0),1)} -> 2400 | AP30: {=INDEX(표2[목표매출액(고객당)],MATCH($B30&AP$28,표2[이름]&표2[월],0),1)} -> 2500 | AQ30: {=INDEX(표2[목표매출액(고객당)],MATCH($B30&AQ$28,표2[이름]&표2[월],0),1)} -> 2600 | AR30: {=INDEX(표2[목표매출액(고객당)],MATCH($B30&AR$28,표2[이름]&표2[월],0),1)} -> 2400
B31: 안동휘 | C31: {=INDEX(표2[매출액],MATCH($B31&C$28,표2[이름]&표2[월],0),1)} -> 159000 | D31: {=INDEX(표2[매출액],MATCH($B31&D$28,표2[이름]&표2[월],0),1)} -> 147000 | E31: {=INDEX(표2[매출액],MATCH($B31&E$28,표2[이름]&표2[월],0),1)} -> 126000 | F31: {=INDEX(표2[목표매출액],MATCH($B31&F$28,표2[이름]&표2[월],0),1)} -> 121000 | G31: {=INDEX(표2[목표매출액],MATCH($B31&G$28,표2[이름]&표2[월],0),1)} -> 174000 | H31: {=INDEX(표2[목표매출액],MATCH($B31&H$28,표2[이름]&표2[월],0),1)} -> 102000 | I31: {=INDEX(표2[전년도매출액],MATCH($B31&I$28,표2[이름]&표2[월],0),1)} -> 126000 | J31: {=INDEX(표2[전년도매출액],MATCH($B31&J$28,표2[이름]&표2[월],0),1)} -> 117000 | K31: {=INDEX(표2[전년도매출액],MATCH($B31&K$28,표2[이름]&표2[월],0),1)} -> 194000 | L31: {=INDEX(표2[전체고객수],MATCH($B31&L$28,표2[이름]&표2[월],0),1)} -> 59 | M31: {=INDEX(표2[전체고객수],MATCH($B31&M$28,표2[이름]&표2[월],0),1)} -> 39 | N31: {=INDEX(표2[전체고객수],MATCH($B31&N$28,표2[이름]&표2[월],0),1)} -> 82 | O31: {=INDEX(표2[목표신규고객수],MATCH($B31&O$28,표2[이름]&표2[월],0),1)} -> 68 | P31: {=INDEX(표2[목표신규고객수],MATCH($B31&P$28,표2[이름]&표2[월],0),1)} -> 83 | Q31: {=INDEX(표2[목표신규고객수],MATCH($B31&Q$28,표2[이름]&표2[월],0),1)} -> 39 | R31: {=INDEX(표2[신규고객수],MATCH($B31&R$28,표2[이름]&표2[월],0),1)} -> 12 | S31: {=INDEX(표2[신규고객수],MATCH($B31&S$28,표2[이름]&표2[월],0),1)} -> 10 | T31: {=INDEX(표2[신규고객수],MATCH($B31&T$28,표2[이름]&표2[월],0),1)} -> 24 | U31: {=INDEX(표2[전년도신규고객수],MATCH($B31&U$28,표2[이름]&표2[월],0),1)} -> 17 | V31: {=INDEX(표2[전년도신규고객수],MATCH($B31&V$28,표2[이름]&표2[월],0),1)} -> 23 | W31: {=INDEX(표2[전년도신규고객수],MATCH($B31&W$28,표2[이름]&표2[월],0),1)} -> 10 | X31: {=INDEX(표2[고객확보비용],MATCH($B31&X$28,표2[이름]&표2[월],0),1)} -> 9600 | Y31: {=INDEX(표2[고객확보비용],MATCH($B31&Y$28,표2[이름]&표2[월],0),1)} -> 7600 | Z31: {=INDEX(표2[고객확보비용],MATCH($B31&Z$28,표2[이름]&표2[월],0),1)} -> 5600 | AA31: =X31/R31 -> 800 | AB31: =Y31/S31 -> 760 | AC31: =Z31/T31 -> 233.33333 | AD31: {=INDEX(표2[고객확보비용목표(고객당)],MATCH($B31&AD$28,표2[이름]&표2[월],0),1)} -> 350 | AE31: {=INDEX(표2[고객확보비용목표(고객당)],MATCH($B31&AE$28,표2[이름]&표2[월],0),1)} -> 350 | AF31: {=INDEX(표2[고객확보비용목표(고객당)],MATCH($B31&AF$28,표2[이름]&표2[월],0),1)} -> 350 | AG31: {=INDEX(표2[전년도고객확보비용(고객당)],MATCH($B31&AG$28,표2[이름]&표2[월],0),1)} -> 358 | AH31: {=INDEX(표2[전년도고객확보비용(고객당)],MATCH($B31&AH$28,표2[이름]&표2[월],0),1)} -> 402 | AI31: {=INDEX(표2[전년도고객확보비용(고객당)],MATCH($B31&AI$28,표2[이름]&표2[월],0),1)} -> 409 | AJ31: =C31/L31 -> 2694.9153 | AK31: =D31/M31 -> 3769.2308 | AL31: =E31/N31 -> 1536.5854 | AM31: {=INDEX(표2[전년도매출액(고객당)],MATCH($B31&AM$28,표2[이름]&표2[월],0),1)} -> 3200 | AN31: {=INDEX(표2[전년도매출액(고객당)],MATCH($B31&AN$28,표2[이름]&표2[월],0),1)} -> 2100 | AO31: {=INDEX(표2[전년도매출액(고객당)],MATCH($B31&AO$28,표2[이름]&표2[월],0),1)} -> 2500 | AP31: {=INDEX(표2[목표매출액(고객당)],MATCH($B31&AP$28,표2[이름]&표2[월],0),1)} -> 2500 | AQ31: {=INDEX(표2[목표매출액(고객당)],MATCH($B31&AQ$28,표2[이름]&표2[월],0),1)} -> 2600 | AR31: {=INDEX(표2[목표매출액(고객당)],MATCH($B31&AR$28,표2[이름]&표2[월],0),1)} -> 2400
B32: 남범수 | C32: {=INDEX(표2[매출액],MATCH($B32&C$28,표2[이름]&표2[월],0),1)} -> 145000 | D32: {=INDEX(표2[매출액],MATCH($B32&D$28,표2[이름]&표2[월],0),1)} -> 181000 | E32: {=INDEX(표2[매출액],MATCH($B32&E$28,표2[이름]&표2[월],0),1)} -> 124000 | F32: {=INDEX(표2[목표매출액],MATCH($B32&F$28,표2[이름]&표2[월],0),1)} -> 176000 | G32: {=INDEX(표2[목표매출액],MATCH($B32&G$28,표2[이름]&표2[월],0),1)} -> 172000 | H32: {=INDEX(표2[목표매출액],MATCH($B32&H$28,표2[이름]&표2[월],0),1)} -> 182000 | I32: {=INDEX(표2[전년도매출액],MATCH($B32&I$28,표2[이름]&표2[월],0),1)} -> 140000 | J32: {=INDEX(표2[전년도매출액],MATCH($B32&J$28,표2[이름]&표2[월],0),1)} -> 122000 | K32: {=INDEX(표2[전년도매출액],MATCH($B32&K$28,표2[이름]&표2[월],0),1)} -> 149000 | L32: {=INDEX(표2[전체고객수],MATCH($B32&L$28,표2[이름]&표2[월],0),1)} -> 41 | M32: {=INDEX(표2[전체고객수],MATCH($B32&M$28,표2[이름]&표2[월],0),1)} -> 84 | N32: {=INDEX(표2[전체고객수],MATCH($B32&N$28,표2[이름]&표2[월],0),1)} -> 52 | O32: {=INDEX(표2[목표신규고객수],MATCH($B32&O$28,표2[이름]&표2[월],0),1)} -> 37 | P32: {=INDEX(표2[목표신규고객수],MATCH($B32&P$28,표2[이름]&표2[월],0),1)} -> 75 | Q32: {=INDEX(표2[목표신규고객수],MATCH($B32&Q$28,표2[이름]&표2[월],0),1)} -> 79 | R32: {=INDEX(표2[신규고객수],MATCH($B32&R$28,표2[이름]&표2[월],0),1)} -> 9 | S32: {=INDEX(표2[신규고객수],MATCH($B32&S$28,표2[이름]&표2[월],0),1)} -> 24 | T32: {=INDEX(표2[신규고객수],MATCH($B32&T$28,표2[이름]&표2[월],0),1)} -> 9 | U32: {=INDEX(표2[전년도신규고객수],MATCH($B32&U$28,표2[이름]&표2[월],0),1)} -> 22 | V32: {=INDEX(표2[전년도신규고객수],MATCH($B32&V$28,표2[이름]&표2[월],0),1)} -> 19 | W32: {=INDEX(표2[전년도신규고객수],MATCH($B32&W$28,표2[이름]&표2[월],0),1)} -> 23 | X32: {=INDEX(표2[고객확보비용],MATCH($B32&X$28,표2[이름]&표2[월],0),1)} -> 6800 | Y32: {=INDEX(표2[고객확보비용],MATCH($B32&Y$28,표2[이름]&표2[월],0),1)} -> 7700 | Z32: {=INDEX(표2[고객확보비용],MATCH($B32&Z$28,표2[이름]&표2[월],0),1)} -> 5600 | AA32: =X32/R32 -> 755.55556 | AB32: =Y32/S32 -> 320.83333 | AC32: =Z32/T32 -> 622.22222 | AD32: {=INDEX(표2[고객확보비용목표(고객당)],MATCH($B32&AD$28,표2[이름]&표2[월],0),1)} -> 350 | AE32: {=INDEX(표2[고객확보비용목표(고객당)],MATCH($B32&AE$28,표2[이름]&표2[월],0),1)} -> 350 | AF32: {=INDEX(표2[고객확보비용목표(고객당)],MATCH($B32&AF$28,표2[이름]&표2[월],0),1)} -> 350 | AG32: {=INDEX(표2[전년도고객확보비용(고객당)],MATCH($B32&AG$28,표2[이름]&표2[월],0),1)} -> 403 | AH32: {=INDEX(표2[전년도고객확보비용(고객당)],MATCH($B32&AH$28,표2[이름]&표2[월],0),1)} -> 399 | AI32: {=INDEX(표2[전년도고객확보비용(고객당)],MATCH($B32&AI$28,표2[이름]&표2[월],0),1)} -> 404 | AJ32: =C32/L32 -> 3536.5854 | AK32: =D32/M32 -> 2154.7619 | AL32: =E32/N32 -> 2384.6154 | AM32: {=INDEX(표2[전년도매출액(고객당)],MATCH($B32&AM$28,표2[이름]&표2[월],0),1)} -> 2500 | AN32: {=INDEX(표2[전년도매출액(고객당)],MATCH($B32&AN$28,표2[이름]&표2[월],0),1)} -> 2100 | AO32: {=INDEX(표2[전년도매출액(고객당)],MATCH($B32&AO$28,표2[이름]&표2[월],0),1)} -> 2000 | AP32: {=INDEX(표2[목표매출액(고객당)],MATCH($B32&AP$28,표2[이름]&표2[월],0),1)} -> 2500 | AQ32: {=INDEX(표2[목표매출액(고객당)],MATCH($B32&AQ$28,표2[이름]&표2[월],0),1)} -> 2600 | AR32: {=INDEX(표2[목표매출액(고객당)],MATCH($B32&AR$28,표2[이름]&표2[월],0),1)} -> 2400
B33: 오지훈 | C33: {=INDEX(표2[매출액],MATCH($B33&C$28,표2[이름]&표2[월],0),1)} -> 158000 | D33: {=INDEX(표2[매출액],MATCH($B33&D$28,표2[이름]&표2[월],0),1)} -> 108000 | E33: {=INDEX(표2[매출액],MATCH($B33&E$28,표2[이름]&표2[월],0),1)} -> 100000 | F33: {=INDEX(표2[목표매출액],MATCH($B33&F$28,표2[이름]&표2[월],0),1)} -> 186000 | G33: {=INDEX(표2[목표매출액],MATCH($B33&G$28,표2[이름]&표2[월],0),1)} -> 107000 | H33: {=INDEX(표2[목표매출액],MATCH($B33&H$28,표2[이름]&표2[월],0),1)} -> 129000 | I33: {=INDEX(표2[전년도매출액],MATCH($B33&I$28,표2[이름]&표2[월],0),1)} -> 187000 | J33: {=INDEX(표2[전년도매출액],MATCH($B33&J$28,표2[이름]&표2[월],0),1)} -> 141000 | K33: {=INDEX(표2[전년도매출액],MATCH($B33&K$28,표2[이름]&표2[월],0),1)} -> 115000 | L33: {=INDEX(표2[전체고객수],MATCH($B33&L$28,표2[이름]&표2[월],0),1)} -> 63 | M33: {=INDEX(표2[전체고객수],MATCH($B33&M$28,표2[이름]&표2[월],0),1)} -> 78 | N33: {=INDEX(표2[전체고객수],MATCH($B33&N$28,표2[이름]&표2[월],0),1)} -> 58 | O33: {=INDEX(표2[목표신규고객수],MATCH($B33&O$28,표2[이름]&표2[월],0),1)} -> 54 | P33: {=INDEX(표2[목표신규고객수],MATCH($B33&P$28,표2[이름]&표2[월],0),1)} -> 46 | Q33: {=INDEX(표2[목표신규고객수],MATCH($B33&Q$28,표2[이름]&표2[월],0),1)} -> 47 | R33: {=INDEX(표2[신규고객수],MATCH($B33&R$28,표2[이름]&표2[월],0),1)} -> 9 | S33: {=INDEX(표2[신규고객수],MATCH($B33&S$28,표2[이름]&표2[월],0),1)} -> 8 | T33: {=INDEX(표2[신규고객수],MATCH($B33&T$28,표2[이름]&표2[월],0),1)} -> 12 | U33: {=INDEX(표2[전년도신규고객수],MATCH($B33&U$28,표2[이름]&표2[월],0),1)} -> 12 | V33: {=INDEX(표2[전년도신규고객수],MATCH($B33&V$28,표2[이름]&표2[월],0),1)} -> 12 | W33: {=INDEX(표2[전년도신규고객수],MATCH($B33&W$28,표2[이름]&표2[월],0),1)} -> 13 | X33: {=INDEX(표2[고객확보비용],MATCH($B33&X$28,표2[이름]&표2[월],0),1)} -> 5800 | Y33: {=INDEX(표2[고객확보비용],MATCH($B33&Y$28,표2[이름]&표2[월],0),1)} -> 9100 | Z33: {=INDEX(표2[고객확보비용],MATCH($B33&Z$28,표2[이름]&표2[월],0),1)} -> 7300 | AA33: =X33/R33 -> 644.44444 | AB33: =Y33/S33 -> 1137.5 | AC33: =Z33/T33 -> 608.33333 | AD33: {=INDEX(표2[고객확보비용목표(고객당)],MATCH($B33&AD$28,표2[이름]&표2[월],0),1)} -> 350 | AE33: {=INDEX(표2[고객확보비용목표(고객당)],MATCH($B33&AE$28,표2[이름]&표2[월],0),1)} -> 350 | AF33: {=INDEX(표2[고객확보비용목표(고객당)],MATCH($B33&AF$28,표2[이름]&표2[월],0),1)} -> 350 | AG33: {=INDEX(표2[전년도고객확보비용(고객당)],MATCH($B33&AG$28,표2[이름]&표2[월],0),1)} -> 392 | AH33: {=INDEX(표2[전년도고객확보비용(고객당)],MATCH($B33&AH$28,표2[이름]&표2[월],0),1)} -> 372 | AI33: {=INDEX(표2[전년도고객확보비용(고객당)],MATCH($B33&AI$28,표2[이름]&표2[월],0),1)} -> 375 | AJ33: =C33/L33 -> 2507.9365 | AK33: =D33/M33 -> 1384.6154 | AL33: =E33/N33 -> 1724.1379 | AM33: {=INDEX(표2[전년도매출액(고객당)],MATCH($B33&AM$28,표2[이름]&표2[월],0),1)} -> 3300 | AN33: {=INDEX(표2[전년도매출액(고객당)],MATCH($B33&AN$28,표2[이름]&표2[월],0),1)} -> 2700 | AO33: {=INDEX(표2[전년도매출액(고객당)],MATCH($B33&AO$28,표2[이름]&표2[월],0),1)} -> 2200 | AP33: {=INDEX(표2[목표매출액(고객당)],MATCH($B33&AP$28,표2[이름]&표2[월],0),1)} -> 2500 | AQ33: {=INDEX(표2[목표매출액(고객당)],MATCH($B33&AQ$28,표2[이름]&표2[월],0),1)} -> 2600 | AR33: {=INDEX(표2[목표매출액(고객당)],MATCH($B33&AR$28,표2[이름]&표2[월],0),1)} -> 2400
B34: 박지수 | C34: {=INDEX(표2[매출액],MATCH($B34&C$28,표2[이름]&표2[월],0),1)} -> 163000 | D34: {=INDEX(표2[매출액],MATCH($B34&D$28,표2[이름]&표2[월],0),1)} -> 182000 | E34: {=INDEX(표2[매출액],MATCH($B34&E$28,표2[이름]&표2[월],0),1)} -> 135000 | F34: {=INDEX(표2[목표매출액],MATCH($B34&F$28,표2[이름]&표2[월],0),1)} -> 171000 | G34: {=INDEX(표2[목표매출액],MATCH($B34&G$28,표2[이름]&표2[월],0),1)} -> 108000 | H34: {=INDEX(표2[목표매출액],MATCH($B34&H$28,표2[이름]&표2[월],0),1)} -> 184000 | I34: {=INDEX(표2[전년도매출액],MATCH($B34&I$28,표2[이름]&표2[월],0),1)} -> 166000 | J34: {=INDEX(표2[전년도매출액],MATCH($B34&J$28,표2[이름]&표2[월],0),1)} -> 153000 | K34: {=INDEX(표2[전년도매출액],MATCH($B34&K$28,표2[이름]&표2[월],0),1)} -> 137000 | L34: {=INDEX(표2[전체고객수],MATCH($B34&L$28,표2[이름]&표2[월],0),1)} -> 66 | M34: {=INDEX(표2[전체고객수],MATCH($B34&M$28,표2[이름]&표2[월],0),1)} -> 75 | N34: {=INDEX(표2[전체고객수],MATCH($B34&N$28,표2[이름]&표2[월],0),1)} -> 53 | O34: {=INDEX(표2[목표신규고객수],MATCH($B34&O$28,표2[이름]&표2[월],0),1)} -> 82 | P34: {=INDEX(표2[목표신규고객수],MATCH($B34&P$28,표2[이름]&표2[월],0),1)} -> 82 | Q34: {=INDEX(표2[목표신규고객수],MATCH($B34&Q$28,표2[이름]&표2[월],0),1)} -> 58 | R34: {=INDEX(표2[신규고객수],MATCH($B34&R$28,표2[이름]&표2[월],0),1)} -> 19 | S34: {=INDEX(표2[신규고객수],MATCH($B34&S$28,표2[이름]&표2[월],0),1)} -> 17 | T34: {=INDEX(표2[신규고객수],MATCH($B34&T$28,표2[이름]&표2[월],0),1)} -> 5 | U34: {=INDEX(표2[전년도신규고객수],MATCH($B34&U$28,표2[이름]&표2[월],0),1)} -> 24 | V34: {=INDEX(표2[전년도신규고객수],MATCH($B34&V$28,표2[이름]&표2[월],0),1)} -> 11 | W34: {=INDEX(표2[전년도신규고객수],MATCH($B34&W$28,표2[이름]&표2[월],0),1)} -> 24 | X34: {=INDEX(표2[고객확보비용],MATCH($B34&X$28,표2[이름]&표2[월],0),1)} -> 5200 | Y34: {=INDEX(표2[고객확보비용],MATCH($B34&Y$28,표2[이름]&표2[월],0),1)} -> 8900 | Z34: {=INDEX(표2[고객확보비용],MATCH($B34&Z$28,표2[이름]&표2[월],0),1)} -> 6800 | AA34: =X34/R34 -> 273.68421 | AB34: =Y34/S34 -> 523.52941 | AC34: =Z34/T34 -> 1360 | AD34: {=INDEX(표2[고객확보비용목표(고객당)],MATCH($B34&AD$28,표2[이름]&표2[월],0),1)} -> 350 | AE34: {=INDEX(표2[고객확보비용목표(고객당)],MATCH($B34&AE$28,표2[이름]&표2[월],0),1)} -> 350 | AF34: {=INDEX(표2[고객확보비용목표(고객당)],MATCH($B34&AF$28,표2[이름]&표2[월],0),1)} -> 350 | AG34: {=INDEX(표2[전년도고객확보비용(고객당)],MATCH($B34&AG$28,표2[이름]&표2[월],0),1)} -> 370 | AH34: {=INDEX(표2[전년도고객확보비용(고객당)],MATCH($B34&AH$28,표2[이름]&표2[월],0),1)} -> 375 | AI34: {=INDEX(표2[전년도고객확보비용(고객당)],MATCH($B34&AI$28,표2[이름]&표2[월],0),1)} -> 353 | AJ34: =C34/L34 -> 2469.697 | AK34: =D34/M34 -> 2426.6667 | AL34: =E34/N34 -> 2547.1698 | AM34: {=INDEX(표2[전년도매출액(고객당)],MATCH($B34&AM$28,표2[이름]&표2[월],0),1)} -> 2300 | AN34: {=INDEX(표2[전년도매출액(고객당)],MATCH($B34&AN$28,표2[이름]&표2[월],0),1)} -> 3100 | AO34: {=INDEX(표2[전년도매출액(고객당)],MATCH($B34&AO$28,표2[이름]&표2[월],0),1)} -> 3100 | AP34: {=INDEX(표2[목표매출액(고객당)],MATCH($B34&AP$28,표2[이름]&표2[월],0),1)} -> 2500 | AQ34: {=INDEX(표2[목표매출액(고객당)],MATCH($B34&AQ$28,표2[이름]&표2[월],0),1)} -> 2600 | AR34: {=INDEX(표2[목표매출액(고객당)],MATCH($B34&AR$28,표2[이름]&표2[월],0),1)} -> 2400
B35: 총합 | C35: =SUM(C30:C34) -> 777000 | D35: =SUM(D30:D34) -> 729000 | E35: =SUM(E30:E34) -> 667000 | F35: =SUM(F30:F34) -> 847000 | G35: =SUM(G30:G34) -> 705000 | H35: =SUM(H30:H34) -> 766000 | I35: =SUM(I30:I34) -> 772000 | J35: =SUM(J30:J34) -> 665000 | ... Z35: =SUM(Z30:Z34) -> 33200 | AA35: =AVERAGE(AA30:AA34) -> 557.08978 | AB35: =AVERAGE(AB30:AB34) -> 647.12255 | AC35: =AVERAGE(AC30:AC34) -> 652.55556 | AD35: =AVERAGE(AD30:AD34) -> 350 | AE35: =AVERAGE(AE30:AE34) -> 350 | AF35: =AVERAGE(AF30:AF34) -> 350 | AG35: =AVERAGE(AG30:AG34) -> 386.6 | AH35: =AVERAGE(AH30:AH34) -> 390.6 | ... AR35: =AVERAGE(AR30:AR34) -> 2400
C38: =H2 -> Q2 2023
C39: 4월 | D39: 5월 | E39: 6월 | F39: 4월 | G39: 5월 | H39: 6월 | I39: 4월 | J39: 5월 | K39: 6월 | L39: 4월 | M39: 5월 | N39: 6월 | O39: 4월 | P39: 5월 | Q39: 6월 | R39: 4월 | S39: 5월 | T39: 6월 | U39: 4월 | V39: 5월 | W39: 6월 | X39: 4월 | Y39: 5월 | Z39: 6월 | AA39: 4월 | AB39: 5월 | AC39: 6월 | AD39: 4월 | AE39: 5월 | AF39: 6월 | AG39: 4월 | AH39: 5월 | AI39: 6월 | AJ39: 4월 | AK39: 5월 | AL39: 6월 | AM39: 4월 | AN39: 5월 | AO39: 6월 | AP39: 4월 | AQ39: 5월 | AR39: 6월
C40: 매출액 | D40: 매출액 | E40: 매출액 | F40: 목표 매출액 | G40: 목표 매출액 | H40: 목표 매출액 | I40: 전년도 매출액 | J40: 전년도 매출액 | K40: 전년도 매출액 | L40: 전체 고객 수 | M40: 전체 고객 수 | N40: 전체 고객 수 | O40: 목표 신규 고객 수 | P40: 목표 신규 고객 수 | Q40: 목표 신규 고객 수 | R40: 신규 고객 수 | S40: 신규 고객 수 | T40: 신규 고객 수 | U40: 전년도 신규 고객 수 | V40: 전년도 신규 고객 수 | W40: 전년도 신규 고객 수 | X40: 고객 확보 비용 | Y40: 고객 확보 비용 | Z40: 고객 확보 비용 | AA40: 고객 당 고객 확보 비용 | AB40: 고객 당 고객 확보 비용 | AC40: 고객 당 고객 확보 비용 | AD40: 고객 확보 비용 목표 (고객 당) | AE40: 고객 확보 비용 목표 (고객 당) | AF40: 고객 확보 비용 목표 (고객 당) | AG40: 전년도 고객 확보 비용 (고객 당) | AH40: 전년도 고객 확보 비용 (고객 당) | AI40: 전년도 고객 확보 비용 (고객 당) | AJ40: 매출액 (고객당) | AK40: 매출액 (고객당) | AL40: 매출액 (고객당) | AM40: 전년도 매출액 (고객당) | AN40: 전년도 매출액 (고객당) | AO40: 전년도 매출액 (고객당) | AP40: 목표 매출액 (고객당) | AQ40: 목표 매출액 (고객당) | AR40: 목표 매출액 (고객당)
B41: 김기범 | C41: {=INDEX(표2[매출액],MATCH($B41&C$39,표2[이름]&표2[월],0),1)} -> 104000 | D41: {=INDEX(표2[매출액],MATCH($B41&D$39,표2[이름]&표2[월],0),1)} -> 190000 | E41: {=INDEX(표2[매출액],MATCH($B41&E$39,표2[이름]&표2[월],0),1)} -> 121000 | F41: {=INDEX(표2[목표매출액],MATCH($B41&F$39,표2[이름]&표2[월],0),1)} -> 126000 | G41: {=INDEX(표2[목표매출액],MATCH($B41&G$39,표2[이름]&표2[월],0),1)} -> 128000 | H41: {=INDEX(표2[목표매출액],MATCH($B41&H$39,표2[이름]&표2[월],0),1)} -> 196000 | I41: {=INDEX(표2[전년도매출액],MATCH($B41&I$39,표2[이름]&표2[월],0),1)} -> 115000 | J41: {=INDEX(표2[전년도매출액],MATCH($B41&J$39,표2[이름]&표2[월],0),1)} -> 119000 | K41: {=INDEX(표2[전년도매출액],MATCH($B41&K$39,표2[이름]&표2[월],0),1)} -> 124000 | L41: {=INDEX(표2[전체고객수],MATCH($B41&L$39,표2[이름]&표2[월],0),1)} -> 68 | M41: {=INDEX(표2[전체고객수],MATCH($B41&M$39,표2[이름]&표2[월],0),1)} -> 78 | N41: {=INDEX(표2[전체고객수],MATCH($B41&N$39,표2[이름]&표2[월],0),1)} -> 80 | O41: {=INDEX(표2[목표신규고객수],MATCH($B41&O$39,표2[이름]&표2[월],0),1)} -> 75 | P41: {=INDEX(표2[목표신규고객수],MATCH($B41&P$39,표2[이름]&표2[월],0),1)} -> 78 | Q41: {=INDEX(표2[목표신규고객수],MATCH($B41&Q$39,표2[이름]&표2[월],0),1)} -> 69 | R41: {=INDEX(표2[신규고객수],MATCH($B41&R$39,표2[이름]&표2[월],0),1)} -> 18 | S41: {=INDEX(표2[신규고객수],MATCH($B41&S$39,표2[이름]&표2[월],0),1)} -> 21 | T41: {=INDEX(표2[신규고객수],MATCH($B41&T$39,표2[이름]&표2[월],0),1)} -> 14 | U41: {=INDEX(표2[전년도신규고객수],MATCH($B41&U$39,표2[이름]&표2[월],0),1)} -> 9 | V41: {=INDEX(표2[전년도신규고객수],MATCH($B41&V$39,표2[이름]&표2[월],0),1)} -> 23 | W41: {=INDEX(표2[전년도신규고객수],MATCH($B41&W$39,표2[이름]&표2[월],0),1)} -> 14 | X41: {=INDEX(표2[고객확보비용],MATCH($B41&X$39,표2[이름]&표2[월],0),1)} -> 9800 | Y41: {=INDEX(표2[고객확보비용],MATCH($B41&Y$39,표2[이름]&표2[월],0),1)} -> 8700 | Z41: {=INDEX(표2[고객확보비용],MATCH($B41&Z$39,표2[이름]&표2[월],0),1)} -> 5600 | AA41: =X41/R41 -> 544.44444 | AB41: =Y41/S41 -> 414.28571 | AC41: =Z41/T41 -> 400 | AD41: {=INDEX(표2[고객확보비용목표(고객당)],MATCH($B41&AD$39,표2[이름]&표2[월],0),1)} -> 400 | AE41: {=INDEX(표2[고객확보비용목표(고객당)],MATCH($B41&AE$39,표2[이름]&표2[월],0),1)} -> 350 | AF41: {=INDEX(표2[고객확보비용목표(고객당)],MATCH($B41&AF$39,표2[이름]&표2[월],0),1)} -> 350 | AG41: {=INDEX(표2[전년도고객확보비용(고객당)],MATCH($B41&AG$39,표2[이름]&표2[월],0),1)} -> 404 | AH41: {=INDEX(표2[전년도고객확보비용(고객당)],MATCH($B41&AH$39,표2[이름]&표2[월],0),1)} -> 379 | AI41: {=INDEX(표2[전년도고객확보비용(고객당)],MATCH($B41&AI$39,표2[이름]&표2[월],0),1)} -> 386 | AJ41: =C41/L41 -> 1529.4118 | AK41: =D41/M41 -> 2435.8974 | AL41: =E41/N41 -> 1512.5 | AM41: {=INDEX(표2[전년도매출액(고객당)],MATCH($B41&AM$39,표2[이름]&표2[월],0),1)} -> 2500 | AN41: {=INDEX(표2[전년도매출액(고객당)],MATCH($B41&AN$39,표2[이름]&표2[월],0),1)} -> 2500 | AO41: {=INDEX(표2[전년도매출액(고객당)],MATCH($B41&AO$39,표2[이름]&표2[월],0),1)} -> 2000 | AP41: {=INDEX(표2[목표매출액(고객당)],MATCH($B41&AP$39,표2[이름]&표2[월],0),1)} -> 2700 | AQ41: {=INDEX(표2[목표매출액(고객당)],MATCH($B41&AQ$39,표2[이름]&표2[월],0),1)} -> 2500 | AR41: {=INDEX(표2[목표매출액(고객당)],MATCH($B41&AR$39,표2[이름]&표2[월],0),1)} -> 2600
B42: 안동휘 | C42: {=INDEX(표2[매출액],MATCH($B42&C$39,표2[이름]&표2[월],0),1)} -> 166000 | D42: {=INDEX(표2[매출액],MATCH($B42&D$39,표2[이름]&표2[월],0),1)} -> 158000 | E42: {=INDEX(표2[매출액],MATCH($B42&E$39,표2[이름]&표2[월],0),1)} -> 116000 | F42: {=INDEX(표2[목표매출액],MATCH($B42&F$39,표2[이름]&표2[월],0),1)} -> 131000 | G42: {=INDEX(표2[목표매출액],MATCH($B42&G$39,표2[이름]&표2[월],0),1)} -> 169000 | H42: {=INDEX(표2[목표매출액],MATCH($B42&H$39,표2[이름]&표2[월],0),1)} -> 193000 | I42: {=INDEX(표2[전년도매출액],MATCH($B42&I$39,표2[이름]&표2[월],0),1)} -> 178000 | J42: {=INDEX(표2[전년도매출액],MATCH($B42&J$39,표2[이름]&표2[월],0),1)} -> 157000 | K42: {=INDEX(표2[전년도매출액],MATCH($B42&K$39,표2[이름]&표2[월],0),1)} -> 178000 | L42: {=INDEX(표2[전체고객수],MATCH($B42&L$39,표2[이름]&표2[월],0),1)} -> 45 | M42: {=INDEX(표2[전체고객수],MATCH($B42&M$39,표2[이름]&표2[월],0),1)} -> 58 | N42: {=INDEX(표2[전체고객수],MATCH($B42&N$39,표2[이름]&표2[월],0),1)} -> 70 | O42: {=INDEX(표2[목표신규고객수],MATCH($B42&O$39,표2[이름]&표2[월],0),1)} -> 31 | P42: {=INDEX(표2[목표신규고객수],MATCH($B42&P$39,표2[이름]&표2[월],0),1)} -> 31 | Q42: {=INDEX(표2[목표신규고객수],MATCH($B42&Q$39,표2[이름]&표2[월],0),1)} -> 46 | R42: {=INDEX(표2[신규고객수],MATCH($B42&R$39,표2[이름]&표2[월],0),1)} -> 7 | S42: {=INDEX(표2[신규고객수],MATCH($B42&S$39,표2[이름]&표2[월],0),1)} -> 6 | T42: {=INDEX(표2[신규고객수],MATCH($B42&T$39,표2[이름]&표2[월],0),1)} -> 9 | U42: {=INDEX(표2[전년도신규고객수],MATCH($B42&U$39,표2[이름]&표2[월],0),1)} -> 19 | V42: {=INDEX(표2[전년도신규고객수],MATCH($B42&V$39,표2[이름]&표2[월],0),1)} -> 11 | W42: {=INDEX(표2[전년도신규고객수],MATCH($B42&W$39,표2[이름]&표2[월],0),1)} -> 14 | X42: {=INDEX(표2[고객확보비용],MATCH($B42&X$39,표2[이름]&표2[월],0),1)} -> 5300 | Y42: {=INDEX(표2[고객확보비용],MATCH($B42&Y$39,표2[이름]&표2[월],0),1)} -> 10700 | Z42: {=INDEX(표2[고객확보비용],MATCH($B42&Z$39,표2[이름]&표2[월],0),1)} -> 5300 | AA42: =X42/R42 -> 757.14286 | AB42: =Y42/S42 -> 1783.3333 | AC42: =Z42/T42 -> 588.88889 | AD42: {=INDEX(표2[고객확보비용목표(고객당)],MATCH($B42&AD$39,표2[이름]&표2[월],0),1)} -> 400 | AE42: {=INDEX(표2[고객확보비용목표(고객당)],MATCH($B42&AE$39,표2[이름]&표2[월],0),1)} -> 350 | AF42: {=INDEX(표2[고객확보비용목표(고객당)],MATCH($B42&AF$39,표2[이름]&표2[월],0),1)} -> 350 | AG42: {=INDEX(표2[전년도고객확보비용(고객당)],MATCH($B42&AG$39,표2[이름]&표2[월],0),1)} -> 401 | AH42: {=INDEX(표2[전년도고객확보비용(고객당)],MATCH($B42&AH$39,표2[이름]&표2[월],0),1)} -> 362 | AI42: {=INDEX(표2[전년도고객확보비용(고객당)],MATCH($B42&AI$39,표2[이름]&표2[월],0),1)} -> 391 | AJ42: =C42/L42 -> 3688.8889 | AK42: =D42/M42 -> 2724.1379 | AL42: =E42/N42 -> 1657.1429 | AM42: {=INDEX(표2[전년도매출액(고객당)],MATCH($B42&AM$39,표2[이름]&표2[월],0),1)} -> 2400 | AN42: {=INDEX(표2[전년도매출액(고객당)],MATCH($B42&AN$39,표2[이름]&표2[월],0),1)} -> 2500 | AO42: {=INDEX(표2[전년도매출액(고객당)],MATCH($B42&AO$39,표2[이름]&표2[월],0),1)} -> 3200 | AP42: {=INDEX(표2[목표매출액(고객당)],MATCH($B42&AP$39,표2[이름]&표2[월],0),1)} -> 2700 | AQ42: {=INDEX(표2[목표매출액(고객당)],MATCH($B42&AQ$39,표2[이름]&표2[월],0),1)} -> 2500 | AR42: {=INDEX(표2[목표매출액(고객당)],MATCH($B42&AR$39,표2[이름]&표2[월],0),1)} -> 2600
B43: 남범수 | C43: {=INDEX(표2[매출액],MATCH($B43&C$39,표2[이름]&표2[월],0),1)} -> 141000 | D43: {=INDEX(표2[매출액],MATCH($B43&D$39,표2[이름]&표2[월],0),1)} -> 159000 | E43: {=INDEX(표2[매출액],MATCH($B43&E$39,표2[이름]&표2[월],0),1)} -> 194000 | F43: {=INDEX(표2[목표매출액],MATCH($B43&F$39,표2[이름]&표2[월],0),1)} -> 123000 | G43: {=INDEX(표2[목표매출액],MATCH($B43&G$39,표2[이름]&표2[월],0),1)} -> 142000 | H43: {=INDEX(표2[목표매출액],MATCH($B43&H$39,표2[이름]&표2[월],0),1)} -> 170000 | I43: {=INDEX(표2[전년도매출액],MATCH($B43&I$39,표2[이름]&표2[월],0),1)} -> 150000 | J43: {=INDEX(표2[전년도매출액],MATCH($B43&J$39,표2[이름]&표2[월],0),1)} -> 103000 | K43: {=INDEX(표2[전년도매출액],MATCH($B43&K$39,표2[이름]&표2[월],0),1)} -> 162000 | L43: {=INDEX(표2[전체고객수],MATCH($B43&L$39,표2[이름]&표2[월],0),1)} -> 74 | M43: {=INDEX(표2[전체고객수],MATCH($B43&M$39,표2[이름]&표2[월],0),1)} -> 31 | N43: {=INDEX(표2[전체고객수],MATCH($B43&N$39,표2[이름]&표2[월],0),1)} -> 48 | O43: {=INDEX(표2[목표신규고객수],MATCH($B43&O$39,표2[이름]&표2[월],0),1)} -> 45 | P43: {=INDEX(표2[목표신규고객수],MATCH($B43&P$39,표2[이름]&표2[월],0),1)} -> 40 | Q43: {=INDEX(표2[목표신규고객수],MATCH($B43&Q$39,표2[이름]&표2[월],0),1)} -> 39 | R43: {=INDEX(표2[신규고객수],MATCH($B43&R$39,표2[이름]&표2[월],0),1)} -> 22 | S43: {=INDEX(표2[신규고객수],MATCH($B43&S$39,표2[이름]&표2[월],0),1)} -> 7 | T43: {=INDEX(표2[신규고객수],MATCH($B43&T$39,표2[이름]&표2[월],0),1)} -> 12 | U43: {=INDEX(표2[전년도신규고객수],MATCH($B43&U$39,표2[이름]&표2[월],0),1)} -> 22 | V43: {=INDEX(표2[전년도신규고객수],MATCH($B43&V$39,표2[이름]&표2[월],0),1)} -> 9 | W43: {=INDEX(표2[전년도신규고객수],MATCH($B43&W$39,표2[이름]&표2[월],0),1)} -> 18 | X43: {=INDEX(표2[고객확보비용],MATCH($B43&X$39,표2[이름]&표2[월],0),1)} -> 10900 | Y43: {=INDEX(표2[고객확보비용],MATCH($B43&Y$39,표2[이름]&표2[월],0),1)} -> 7000 | Z43: {=INDEX(표2[고객확보비용],MATCH($B43&Z$39,표2[이름]&표2[월],0),1)} -> 5800 | AA43: =X43/R43 -> 495.45455 | AB43: =Y43/S43 -> 1000 | AC43: =Z43/T43 -> 483.33333 | AD43: {=INDEX(표2[고객확보비용목표(고객당)],MATCH($B43&AD$39,표2[이름]&표2[월],0),1)} -> 400 | AE43: {=INDEX(표2[고객확보비용목표(고객당)],MATCH($B43&AE$39,표2[이름]&표2[월],0),1)} -> 350 | AF43: {=INDEX(표2[고객확보비용목표(고객당)],MATCH($B43&AF$39,표2[이름]&표2[월],0),1)} -> 350 | AG43: {=INDEX(표2[전년도고객확보비용(고객당)],MATCH($B43&AG$39,표2[이름]&표2[월],0),1)} -> 359 | AH43: {=INDEX(표2[전년도고객확보비용(고객당)],MATCH($B43&AH$39,표2[이름]&표2[월],0),1)} -> 384 | AI43: {=INDEX(표2[전년도고객확보비용(고객당)],MATCH($B43&AI$39,표2[이름]&표2[월],0),1)} -> 354 | AJ43: =C43/L43 -> 1905.4054 | AK43: =D43/M43 -> 5129.0323 | AL43: =E43/N43 -> 4041.6667 | AM43: {=INDEX(표2[전년도매출액(고객당)],MATCH($B43&AM$39,표2[이름]&표2[월],0),1)} -> 2500 | AN43: {=INDEX(표2[전년도매출액(고객당)],MATCH($B43&AN$39,표2[이름]&표2[월],0),1)} -> 3200 | AO43: {=INDEX(표2[전년도매출액(고객당)],MATCH($B43&AO$39,표2[이름]&표2[월],0),1)} -> 3300 | AP43: {=INDEX(표2[목표매출액(고객당)],MATCH($B43&AP$39,표2[이름]&표2[월],0),1)} -> 2700 | AQ43: {=INDEX(표2[목표매출액(고객당)],MATCH($B43&AQ$39,표2[이름]&표2[월],0),1)} -> 2500 | AR43: {=INDEX(표2[목표매출액(고객당)],MATCH($B43&AR$39,표2[이름]&표2[월],0),1)} -> 2600
B44: 오지훈 | C44: {=INDEX(표2[매출액],MATCH($B44&C$39,표2[이름]&표2[월],0),1)} -> 109000 | D44: {=INDEX(표2[매출액],MATCH($B44&D$39,표2[이름]&표2[월],0),1)} -> 161000 | E44: {=INDEX(표2[매출액],MATCH($B44&E$39,표2[이름]&표2[월],0),1)} -> 114000 | F44: {=INDEX(표2[목표매출액],MATCH($B44&F$39,표2[이름]&표2[월],0),1)} -> 106000 | G44: {=INDEX(표2[목표매출액],MATCH($B44&G$39,표2[이름]&표2[월],0),1)} -> 126000 | H44: {=INDEX(표2[목표매출액],MATCH($B44&H$39,표2[이름]&표2[월],0),1)} -> 127000 | I44: {=INDEX(표2[전년도매출액],MATCH($B44&I$39,표2[이름]&표2[월],0),1)} -> 126000 | J44: {=INDEX(표2[전년도매출액],MATCH($B44&J$39,표2[이름]&표2[월],0),1)} -> 150000 | K44: {=INDEX(표2[전년도매출액],MATCH($B44&K$39,표2[이름]&표2[월],0),1)} -> 186000 | L44: {=INDEX(표2[전체고객수],MATCH($B44&L$39,표2[이름]&표2[월],0),1)} -> 33 | M44: {=INDEX(표2[전체고객수],MATCH($B44&M$39,표2[이름]&표2[월],0),1)} -> 33 | N44: {=INDEX(표2[전체고객수],MATCH($B44&N$39,표2[이름]&표2[월],0),1)} -> 68 | O44: {=INDEX(표2[목표신규고객수],MATCH($B44&O$39,표2[이름]&표2[월],0),1)} -> 85 | P44: {=INDEX(표2[목표신규고객수],MATCH($B44&P$39,표2[이름]&표2[월],0),1)} -> 59 | Q44: {=INDEX(표2[목표신규고객수],MATCH($B44&Q$39,표2[이름]&표2[월],0),1)} -> 57 | R44: {=INDEX(표2[신규고객수],MATCH($B44&R$39,표2[이름]&표2[월],0),1)} -> 6 | S44: {=INDEX(표2[신규고객수],MATCH($B44&S$39,표2[이름]&표2[월],0),1)} -> 5 | T44: {=INDEX(표2[신규고객수],MATCH($B44&T$39,표2[이름]&표2[월],0),1)} -> 20 | U44: {=INDEX(표2[전년도신규고객수],MATCH($B44&U$39,표2[이름]&표2[월],0),1)} -> 25 | V44: {=INDEX(표2[전년도신규고객수],MATCH($B44&V$39,표2[이름]&표2[월],0),1)} -> 17 | W44: {=INDEX(표2[전년도신규고객수],MATCH($B44&W$39,표2[이름]&표2[월],0),1)} -> 10 | X44: {=INDEX(표2[고객확보비용],MATCH($B44&X$39,표2[이름]&표2[월],0),1)} -> 8300 | Y44: {=INDEX(표2[고객확보비용],MATCH($B44&Y$39,표2[이름]&표2[월],0),1)} -> 6700 | Z44: {=INDEX(표2[고객확보비용],MATCH($B44&Z$39,표2[이름]&표2[월],0),1)} -> 5700 | AA44: =X44/R44 -> 1383.3333 | AB44: =Y44/S44 -> 1340 | AC44: =Z44/T44 -> 285 | AD44: {=INDEX(표2[고객확보비용목표(고객당)],MATCH($B44&AD$39,표2[이름]&표2[월],0),1)} -> 400 | AE44: {=INDEX(표2[고객확보비용목표(고객당)],MATCH($B44&AE$39,표2[이름]&표2[월],0),1)} -> 350 | AF44: {=INDEX(표2[고객확보비용목표(고객당)],MATCH($B44&AF$39,표2[이름]&표2[월],0),1)} -> 350 | AG44: {=INDEX(표2[전년도고객확보비용(고객당)],MATCH($B44&AG$39,표2[이름]&표2[월],0),1)} -> 359 | AH44: {=INDEX(표2[전년도고객확보비용(고객당)],MATCH($B44&AH$39,표2[이름]&표2[월],0),1)} -> 387 | AI44: {=INDEX(표2[전년도고객확보비용(고객당)],MATCH($B44&AI$39,표2[이름]&표2[월],0),1)} -> 355 | AJ44: =C44/L44 -> 3303.0303 | AK44: =D44/M44 -> 4878.7879 | AL44: =E44/N44 -> 1676.4706 | AM44: {=INDEX(표2[전년도매출액(고객당)],MATCH($B44&AM$39,표2[이름]&표2[월],0),1)} -> 2200 | AN44: {=INDEX(표2[전년도매출액(고객당)],MATCH($B44&AN$39,표2[이름]&표2[월],0),1)} -> 2100 | AO44: {=INDEX(표2[전년도매출액(고객당)],MATCH($B44&AO$39,표2[이름]&표2[월],0),1)} -> 3200 | AP44: {=INDEX(표2[목표매출액(고객당)],MATCH($B44&AP$39,표2[이름]&표2[월],0),1)} -> 2700 | AQ44: {=INDEX(표2[목표매출액(고객당)],MATCH($B44&AQ$39,표2[이름]&표2[월],0),1)} -> 2500 | AR44: {=INDEX(표2[목표매출액(고객당)],MATCH($B44&AR$39,표2[이름]&표2[월],0),1)} -> 2600
B45: 박지수 | C45: {=INDEX(표2[매출액],MATCH($B45&C$39,표2[이름]&표2[월],0),1)} -> 164000 | D45: {=INDEX(표2[매출액],MATCH($B45&D$39,표2[이름]&표2[월],0),1)} -> 131000 | E45: {=INDEX(표2[매출액],MATCH($B45&E$39,표2[이름]&표2[월],0),1)} -> 169000 | F45: {=INDEX(표2[목표매출액],MATCH($B45&F$39,표2[이름]&표2[월],0),1)} -> 194000 | G45: {=INDEX(표2[목표매출액],MATCH($B45&G$39,표2[이름]&표2[월],0),1)} -> 104000 | H45: {=INDEX(표2[목표매출액],MATCH($B45&H$39,표2[이름]&표2[월],0),1)} -> 118000 | I45: {=INDEX(표2[전년도매출액],MATCH($B45&I$39,표2[이름]&표2[월],0),1)} -> 165000 | J45: {=INDEX(표2[전년도매출액],MATCH($B45&J$39,표2[이름]&표2[월],0),1)} -> 176000 | K45: {=INDEX(표2[전년도매출액],MATCH($B45&K$39,표2[이름]&표2[월],0),1)} -> 182000 | L45: {=INDEX(표2[전체고객수],MATCH($B45&L$39,표2[이름]&표2[월],0),1)} -> 76 | M45: {=INDEX(표2[전체고객수],MATCH($B45&M$39,표2[이름]&표2[월],0),1)} -> 66 | N45: {=INDEX(표2[전체고객수],MATCH($B45&N$39,표2[이름]&표2[월],0),1)} -> 68 | O45: {=INDEX(표2[목표신규고객수],MATCH($B45&O$39,표2[이름]&표2[월],0),1)} -> 73 | P45: {=INDEX(표2[목표신규고객수],MATCH($B45&P$39,표2[이름]&표2[월],0),1)} -> 65 | Q45: {=INDEX(표2[목표신규고객수],MATCH($B45&Q$39,표2[이름]&표2[월],0),1)} -> 65 | R45: {=INDEX(표2[신규고객수],MATCH($B45&R$39,표2[이름]&표2[월],0),1)} -> 11 | S45: {=INDEX(표2[신규고객수],MATCH($B45&S$39,표2[이름]&표2[월],0),1)} -> 19 | T45: {=INDEX(표2[신규고객수],MATCH($B45&T$39,표2[이름]&표2[월],0),1)} -> 10 | U45: {=INDEX(표2[전년도신규고객수],MATCH($B45&U$39,표2[이름]&표2[월],0),1)} -> 9 | V45: {=INDEX(표2[전년도신규고객수],MATCH($B45&V$39,표2[이름]&표2[월],0),1)} -> 11 | W45: {=INDEX(표2[전년도신규고객수],MATCH($B45&W$39,표2[이름]&표2[월],0),1)} -> 18 | X45: {=INDEX(표2[고객확보비용],MATCH($B45&X$39,표2[이름]&표2[월],0),1)} -> 10600 | Y45: {=INDEX(표2[고객확보비용],MATCH($B45&Y$39,표2[이름]&표2[월],0),1)} -> 7100 | Z45: {=INDEX(표2[고객확보비용],MATCH($B45&Z$39,표2[이름]&표2[월],0),1)} -> 8100 | AA45: =X45/R45 -> 963.63636 | AB45: =Y45/S45 -> 373.68421 | AC45: =Z45/T45 -> 810 | AD45: {=INDEX(표2[고객확보비용목표(고객당)],MATCH($B45&AD$39,표2[이름]&표2[월],0),1)} -> 400 | AE45: {=INDEX(표2[고객확보비용목표(고객당)],MATCH($B45&AE$39,표2[이름]&표2[월],0),1)} -> 350 | AF45: {=INDEX(표2[고객확보비용목표(고객당)],MATCH($B45&AF$39,표2[이름]&표2[월],0),1)} -> 350 | AG45: {=INDEX(표2[전년도고객확보비용(고객당)],MATCH($B45&AG$39,표2[이름]&표2[월],0),1)} -> 354 | AH45: {=INDEX(표2[전년도고객확보비용(고객당)],MATCH($B45&AH$39,표2[이름]&표2[월],0),1)} -> 369 | AI45: {=INDEX(표2[전년도고객확보비용(고객당)],MATCH($B45&AI$39,표2[이름]&표2[월],0),1)} -> 402 | AJ45: =C45/L45 -> 2157.8947 | AK45: =D45/M45 -> 1984.8485 | AL45: =E45/N45 -> 2485.2941 | AM45: {=INDEX(표2[전년도매출액(고객당)],MATCH($B45&AM$39,표2[이름]&표2[월],0),1)} -> 2400 | AN45: {=INDEX(표2[전년도매출액(고객당)],MATCH($B45&AN$39,표2[이름]&표2[월],0),1)} -> 2900 | AO45: {=INDEX(표2[전년도매출액(고객당)],MATCH($B45&AO$39,표2[이름]&표2[월],0),1)} -> 2900 | AP45: {=INDEX(표2[목표매출액(고객당)],MATCH($B45&AP$39,표2[이름]&표2[월],0),1)} -> 2700 | AQ45: {=INDEX(표2[목표매출액(고객당)],MATCH($B45&AQ$39,표2[이름]&표2[월],0),1)} -> 2500 | AR45: {=INDEX(표2[목표매출액(고객당)],MATCH($B45&AR$39,표2[이름]&표2[월],0),1)} -> 2600
B46: 총합 | C46: =SUM(C41:C45) -> 684000 | D46: =SUM(D41:D45) -> 799000 | E46: =SUM(E41:E45) -> 714000 | F46: =SUM(F41:F45) -> 680000 | G46: =SUM(G41:G45) -> 669000 | H46: =SUM(H41:H45) -> 804000 | I46: =SUM(I41:I45) -> 734000 | J46: =SUM(J41:J45) -> 705000 | ... Z46: =SUM(Z41:Z45) -> 30500 | AA46: =AVERAGE(AA41:AA45) -> 828.80231 | AB46: =AVERAGE(AB41:AB45) -> 982.26065 | AC46: =AVERAGE(AC41:AC45) -> 513.44444 | AD46: =AVERAGE(AD41:AD45) -> 400 | AE46: =AVERAGE(AE41:AE45) -> 350 | AF46: =AVERAGE(AF41:AF45) -> 350 | AG46: =AVERAGE(AG41:AG45) -> 375.4 | AH46: =AVERAGE(AH41:AH45) -> 376.2 | ... AR46: =AVERAGE(AR41:AR45) -> 2600
C49: =H3 -> Q3 2023
C50: 7월 | D50: 8월 | E50: 9월 | F50: 7월 | G50: 8월 | H50: 9월 | I50: 7월 | J50: 8월 | K50: 9월 | L50: 7월 | M50: 8월 | N50: 9월 | O50: 7월 | P50: 8월 | Q50: 9월 | R50: 7월 | S50: 8월 | T50: 9월 | U50: 7월 | V50: 8월 | W50: 9월 | X50: 7월 | Y50: 8월 | Z50: 9월 | AA50: 7월 | AB50: 8월 | AC50: 9월 | AD50: 7월 | AE50: 8월 | AF50: 9월 | AG50: 7월 | AH50: 8월 | AI50: 9월 | AJ50: 7월 | AK50: 8월 | AL50: 9월 | AM50: 7월 | AN50: 8월 | AO50: 9월 | AP50: 7월 | AQ50: 8월 | AR50: 9월
C51: 매출액 | D51: 매출액 | E51: 매출액 | F51: 목표 매출액 | G51: 목표 매출액 | H51: 목표 매출액 | I51: 전년도 매출액 | J51: 전년도 매출액 | K51: 전년도 매출액 | L51: 전체 고객 수 | M51: 전체 고객 수 | N51: 전체 고객 수 | O51: 목표 신규 고객 수 | P51: 목표 신규 고객 수 | Q51: 목표 신규 고객 수 | R51: 신규 고객 수 | S51: 신규 고객 수 | T51: 신규 고객 수 | U51: 전년도 신규 고객 수 | V51: 전년도 신규 고객 수 | W51: 전년도 신규 고객 수 | X51: 고객 확보 비용 | Y51: 고객 확보 비용 | Z51: 고객 확보 비용 | AA51: 고객 당 고객 확보 비용 | AB51: 고객 당 고객 확보 비용 | AC51: 고객 당 고객 확보 비용 | AD51: 고객 확보 비용 목표 (고객 당) | AE51: 고객 확보 비용 목표 (고객 당) | AF51: 고객 확보 비용 목표 (고객 당) | AG51: 전년도 고객 확보 비용 (고객 당) | AH51: 전년도 고객 확보 비용 (고객 당) | AI51: 전년도 고객 확보 비용 (고객 당) | AJ51: 매출액 (고객당) | AK51: 매출액 (고객당) | AL51: 매출액 (고객당) | AM51: 전년도 매출액 (고객당) | AN51: 전년도 매출액 (고객당) | AO51: 전년도 매출액 (고객당) | AP51: 목표 매출액 (고객당) | AQ51: 목표 매출액 (고객당) | AR51: 목표 매출액 (고객당)
B52: 김기범 | C52: {=INDEX(표2[매출액],MATCH($B52&C$50,표2[이름]&표2[월],0),1)} -> 157000 | D52: {=INDEX(표2[매출액],MATCH($B52&D$50,표2[이름]&표2[월],0),1)} -> 118000 | E52: {=INDEX(표2[매출액],MATCH($B52&E$50,표2[이름]&표2[월],0),1)} -> 118000 | F52: {=INDEX(표2[목표매출액],MATCH($B52&F$50,표2[이름]&표2[월],0),1)} -> 128000 | G52: {=INDEX(표2[목표매출액],MATCH($B52&G$50,표2[이름]&표2[월],0),1)} -> 162000 | H52: {=INDEX(표2[목표매출액],MATCH($B52&H$50,표2[이름]&표2[월],0),1)} -> 130000 | I52: {=INDEX(표2[전년도매출액],MATCH($B52&I$50,표2[이름]&표2[월],0),1)} -> 103000 | J52: {=INDEX(표2[전년도매출액],MATCH($B52&J$50,표2[이름]&표2[월],0),1)} -> 151000 | K52: {=INDEX(표2[전년도매출액],MATCH($B52&K$50,표2[이름]&표2[월],0),1)} -> 119000 | L52: {=INDEX(표2[전체고객수],MATCH($B52&L$50,표2[이름]&표2[월],0),1)} -> 35 | M52: {=INDEX(표2[전체고객수],MATCH($B52&M$50,표2[이름]&표2[월],0),1)} -> 55 | N52: {=INDEX(표2[전체고객수],MATCH($B52&N$50,표2[이름]&표2[월],0),1)} -> 60 | O52: {=INDEX(표2[목표신규고객수],MATCH($B52&O$50,표2[이름]&표2[월],0),1)} -> 39 | P52: {=INDEX(표2[목표신규고객수],MATCH($B52&P$50,표2[이름]&표2[월],0),1)} -> 80 | Q52: {=INDEX(표2[목표신규고객수],MATCH($B52&Q$50,표2[이름]&표2[월],0),1)} -> 52 | R52: {=INDEX(표2[신규고객수],MATCH($B52&R$50,표2[이름]&표2[월],0),1)} -> 5 | S52: {=INDEX(표2[신규고객수],MATCH($B52&S$50,표2[이름]&표2[월],0),1)} -> 15 | T52: {=INDEX(표2[신규고객수],MATCH($B52&T$50,표2[이름]&표2[월],0),1)} -> 17 | U52: {=INDEX(표2[전년도신규고객수],MATCH($B52&U$50,표2[이름]&표2[월],0),1)} -> 9 | V52: {=INDEX(표2[전년도신규고객수],MATCH($B52&V$50,표2[이름]&표2[월],0),1)} -> 16 | W52: {=INDEX(표2[전년도신규고객수],MATCH($B52&W$50,표2[이름]&표2[월],0),1)} -> 19 | X52: {=INDEX(표2[고객확보비용],MATCH($B52&X$50,표2[이름]&표2[월],0),1)} -> 5900 | Y52: {=INDEX(표2[고객확보비용],MATCH($B52&Y$50,표2[이름]&표2[월],0),1)} -> 6500 | Z52: {=INDEX(표2[고객확보비용],MATCH($B52&Z$50,표2[이름]&표2[월],0),1)} -> 9600 | AA52: =X52/R52 -> 1180 | AB52: =Y52/S52 -> 433.33333 | AC52: =Z52/T52 -> 564.70588 | AD52: {=INDEX(표2[고객확보비용목표(고객당)],MATCH($B52&AD$50,표2[이름]&표2[월],0),1)} -> 350 | AE52: {=INDEX(표2[고객확보비용목표(고객당)],MATCH($B52&AE$50,표2[이름]&표2[월],0),1)} -> 450 | AF52: {=INDEX(표2[고객확보비용목표(고객당)],MATCH($B52&AF$50,표2[이름]&표2[월],0),1)} -> 350 | AG52: {=INDEX(표2[전년도고객확보비용(고객당)],MATCH($B52&AG$50,표2[이름]&표2[월],0),1)} -> 353 | AH52: {=INDEX(표2[전년도고객확보비용(고객당)],MATCH($B52&AH$50,표2[이름]&표2[월],0),1)} -> 388 | AI52: {=INDEX(표2[전년도고객확보비용(고객당)],MATCH($B52&AI$50,표2[이름]&표2[월],0),1)} -> 365 | AJ52: =C52/L52 -> 4485.7143 | AK52: =D52/M52 -> 2145.4545 | AL52: =E52/N52 -> 1966.6667 | AM52: {=INDEX(표2[전년도매출액(고객당)],MATCH($B52&AM$50,표2[이름]&표2[월],0),1)} -> 2200 | AN52: {=INDEX(표2[전년도매출액(고객당)],MATCH($B52&AN$50,표2[이름]&표2[월],0),1)} -> 2300 | AO52: {=INDEX(표2[전년도매출액(고객당)],MATCH($B52&AO$50,표2[이름]&표2[월],0),1)} -> 2400 | AP52: {=INDEX(표2[목표매출액(고객당)],MATCH($B52&AP$50,표2[이름]&표2[월],0),1)} -> 2200 | AQ52: {=INDEX(표2[목표매출액(고객당)],MATCH($B52&AQ$50,표2[이름]&표2[월],0),1)} -> 2300 | AR52: {=INDEX(표2[목표매출액(고객당)],MATCH($B52&AR$50,표2[이름]&표2[월],0),1)} -> 2500
...

Sheet DASHBOARD
C2: KPI 개요 | F2: Q4 2023
C5: 매출액 VS 목표 | L5: 신규 고객 수 VS 목표
C7: =SUM(Calculations!C16:E16) -> 2280000 | E7: 실제 매출액 | L7: =SUM(Calculations!R16:T16) -> 156 | N7: 실제 신규 고객 수
C9: =SUM(Calculations!F16:H16) -> 2294000 | E9: 목표 매출액 | L9: =SUM(Calculations!O16:Q16) -> 857 | N9: 목표 신규 고객 수
C11: =C7/C9 -> 0.99389712 | E11: 목표 달성률 | L11: =L7/L9 -> 0.18203034 | N11: 목표 달성률
C15: 고객 별 매출액 평균 | L15: 고객 확보 비용
C17: =SUM(Calculations!AJ16:AL16)/3 -> 3090.8586 | E17: 고객 별 실제 매출액 | L17: =SUM(Calculations!AA16:AC16)/3 -> 1003.4958 | N17: 실제 고객 확보 비용
C19: =SUM(Calculations!AP16:AR16)/3 -> 2500 | E19: 고객 별 목표 매출액 | L19: =SUM(Calculations!AD16:AF16)/3 -> 333.33333 | N19: 목표 고객 확보 비용
C21: =C17/C19 -> 1.2363435 | E21: 목표 달성률 | L21: =L17/L19 -> 3.0104874 | N21: 목표 달성률
